Traceback (most recent call last):
  File "c:\programdata\anaconda3\lib\site-packages\jupyter_cache\executors\utils.py", line 51, in single_nb_execution
    executenb(
  File "c:\programdata\anaconda3\lib\site-packages\nbclient\client.py", line 1112, in execute
    return NotebookClient(nb=nb, resources=resources, km=km, **kwargs).execute()
  File "c:\programdata\anaconda3\lib\site-packages\nbclient\util.py", line 74, in wrapped
    return just_run(coro(*args, **kwargs))
  File "c:\programdata\anaconda3\lib\site-packages\nbclient\util.py", line 53, in just_run
    return loop.run_until_complete(coro)
  File "c:\programdata\anaconda3\lib\asyncio\base_events.py", line 616, in run_until_complete
    return future.result()
  File "c:\programdata\anaconda3\lib\site-packages\nbclient\client.py", line 553, in async_execute
    await self.async_execute_cell(
  File "c:\programdata\anaconda3\lib\site-packages\nbclient\client.py", line 857, in async_execute_cell
    self._check_raise_for_error(cell, exec_reply)
  File "c:\programdata\anaconda3\lib\site-packages\nbclient\client.py", line 760, in _check_raise_for_error
    raise CellExecutionError.from_cell_and_msg(cell, exec_reply_content)
nbclient.exceptions.CellExecutionError: An error occurred while executing the following cell:
------------------
# Ëß£Â£ìÁ∏Æ
import zipfile
with zipfile.ZipFile(file_name, 'r') as zip_ref:
    zip_ref.extractall(unzip_folder)
------------------

[1;31m---------------------------------------------------------------------------[0m
[1;31mFileNotFoundError[0m                         Traceback (most recent call last)
[1;32m<ipython-input-2-d5b43671ae08>[0m in [0;36m<module>[1;34m[0m
[0;32m      1[0m [1;31m# Ëß£Â£ìÁ∏Æ[0m[1;33m[0m[1;33m[0m[1;33m[0m[0m
[0;32m      2[0m [1;32mimport[0m [0mzipfile[0m[1;33m[0m[1;33m[0m[0m
[1;32m----> 3[1;33m [1;32mwith[0m [0mzipfile[0m[1;33m.[0m[0mZipFile[0m[1;33m([0m[0mfile_name[0m[1;33m,[0m [1;34m'r'[0m[1;33m)[0m [1;32mas[0m [0mzip_ref[0m[1;33m:[0m[1;33m[0m[1;33m[0m[0m
[0m[0;32m      4[0m     [0mzip_ref[0m[1;33m.[0m[0mextractall[0m[1;33m([0m[0munzip_folder[0m[1;33m)[0m[1;33m[0m[1;33m[0m[0m

[1;32mC:\ProgramData\Anaconda3\lib\zipfile.py[0m in [0;36m__init__[1;34m(self, file, mode, compression, allowZip64, compresslevel, strict_timestamps)[0m
[0;32m   1249[0m             [1;32mwhile[0m [1;32mTrue[0m[1;33m:[0m[1;33m[0m[1;33m[0m[0m
[0;32m   1250[0m                 [1;32mtry[0m[1;33m:[0m[1;33m[0m[1;33m[0m[0m
[1;32m-> 1251[1;33m                     [0mself[0m[1;33m.[0m[0mfp[0m [1;33m=[0m [0mio[0m[1;33m.[0m[0mopen[0m[1;33m([0m[0mfile[0m[1;33m,[0m [0mfilemode[0m[1;33m)[0m[1;33m[0m[1;33m[0m[0m
[0m[0;32m   1252[0m                 [1;32mexcept[0m [0mOSError[0m[1;33m:[0m[1;33m[0m[1;33m[0m[0m
[0;32m   1253[0m                     [1;32mif[0m [0mfilemode[0m [1;32min[0m [0mmodeDict[0m[1;33m:[0m[1;33m[0m[1;33m[0m[0m

[1;31mFileNotFoundError[0m: [Errno 2] No such file or directory: './Ê´ªÊ°ÉÂ∞è‰∏∏Â≠ê.zip'
FileNotFoundError: [Errno 2] No such file or directory: './Ê´ªÊ°ÉÂ∞è‰∏∏Â≠ê.zip'

