Traceback (most recent call last):
  File "c:\programdata\anaconda3\lib\site-packages\jupyter_cache\executors\utils.py", line 51, in single_nb_execution
    executenb(
  File "c:\programdata\anaconda3\lib\site-packages\nbclient\client.py", line 1112, in execute
    return NotebookClient(nb=nb, resources=resources, km=km, **kwargs).execute()
  File "c:\programdata\anaconda3\lib\site-packages\nbclient\util.py", line 74, in wrapped
    return just_run(coro(*args, **kwargs))
  File "c:\programdata\anaconda3\lib\site-packages\nbclient\util.py", line 53, in just_run
    return loop.run_until_complete(coro)
  File "c:\programdata\anaconda3\lib\asyncio\base_events.py", line 616, in run_until_complete
    return future.result()
  File "c:\programdata\anaconda3\lib\site-packages\nbclient\client.py", line 553, in async_execute
    await self.async_execute_cell(
  File "c:\programdata\anaconda3\lib\site-packages\nbclient\client.py", line 857, in async_execute_cell
    self._check_raise_for_error(cell, exec_reply)
  File "c:\programdata\anaconda3\lib\site-packages\nbclient\client.py", line 760, in _check_raise_for_error
    raise CellExecutionError.from_cell_and_msg(cell, exec_reply_content)
nbclient.exceptions.CellExecutionError: An error occurred while executing the following cell:
------------------
df['æ—¥æœŸ'] = pd.to_datetime(df['æ—¥æœŸ'])
df.head()
------------------

[1;31m---------------------------------------------------------------------------[0m
[1;31mValueError[0m                                Traceback (most recent call last)
[1;32mC:\ProgramData\Anaconda3\lib\site-packages\dateutil\parser\_parser.py[0m in [0;36mparse[1;34m(self, timestr, default, ignoretz, tzinfos, **kwargs)[0m
[0;32m    654[0m         [1;32mtry[0m[1;33m:[0m[1;33m[0m[1;33m[0m[0m
[1;32m--> 655[1;33m             [0mret[0m [1;33m=[0m [0mself[0m[1;33m.[0m[0m_build_naive[0m[1;33m([0m[0mres[0m[1;33m,[0m [0mdefault[0m[1;33m)[0m[1;33m[0m[1;33m[0m[0m
[0m[0;32m    656[0m         [1;32mexcept[0m [0mValueError[0m [1;32mas[0m [0me[0m[1;33m:[0m[1;33m[0m[1;33m[0m[0m

[1;32mC:\ProgramData\Anaconda3\lib\site-packages\dateutil\parser\_parser.py[0m in [0;36m_build_naive[1;34m(self, res, default)[0m
[0;32m   1240[0m [1;33m[0m[0m
[1;32m-> 1241[1;33m         [0mnaive[0m [1;33m=[0m [0mdefault[0m[1;33m.[0m[0mreplace[0m[1;33m([0m[1;33m**[0m[0mrepl[0m[1;33m)[0m[1;33m[0m[1;33m[0m[0m
[0m[0;32m   1242[0m [1;33m[0m[0m

[1;31mValueError[0m: month must be in 1..12

The above exception was the direct cause of the following exception:

[1;31mParserError[0m                               Traceback (most recent call last)
[1;32mpandas\_libs\tslib.pyx[0m in [0;36mpandas._libs.tslib.array_to_datetime[1;34m()[0m

[1;32mpandas\_libs\tslibs\parsing.pyx[0m in [0;36mpandas._libs.tslibs.parsing.parse_datetime_string[1;34m()[0m

[1;32mC:\ProgramData\Anaconda3\lib\site-packages\dateutil\parser\_parser.py[0m in [0;36mparse[1;34m(timestr, parserinfo, **kwargs)[0m
[0;32m   1373[0m     [1;32melse[0m[1;33m:[0m[1;33m[0m[1;33m[0m[0m
[1;32m-> 1374[1;33m         [1;32mreturn[0m [0mDEFAULTPARSER[0m[1;33m.[0m[0mparse[0m[1;33m([0m[0mtimestr[0m[1;33m,[0m [1;33m**[0m[0mkwargs[0m[1;33m)[0m[1;33m[0m[1;33m[0m[0m
[0m[0;32m   1375[0m [1;33m[0m[0m

[1;32mC:\ProgramData\Anaconda3\lib\site-packages\dateutil\parser\_parser.py[0m in [0;36mparse[1;34m(self, timestr, default, ignoretz, tzinfos, **kwargs)[0m
[0;32m    656[0m         [1;32mexcept[0m [0mValueError[0m [1;32mas[0m [0me[0m[1;33m:[0m[1;33m[0m[1;33m[0m[0m
[1;32m--> 657[1;33m             [0msix[0m[1;33m.[0m[0mraise_from[0m[1;33m([0m[0mParserError[0m[1;33m([0m[0me[0m[1;33m.[0m[0margs[0m[1;33m[[0m[1;36m0[0m[1;33m][0m [1;33m+[0m [1;34m": %s"[0m[1;33m,[0m [0mtimestr[0m[1;33m)[0m[1;33m,[0m [0me[0m[1;33m)[0m[1;33m[0m[1;33m[0m[0m
[0m[0;32m    658[0m [1;33m[0m[0m

[1;32mC:\ProgramData\Anaconda3\lib\site-packages\six.py[0m in [0;36mraise_from[1;34m(value, from_value)[0m

[1;31mParserError[0m: month must be in 1..12: 2113--0-01

During handling of the above exception, another exception occurred:

[1;31mTypeError[0m                                 Traceback (most recent call last)
[1;32mpandas\_libs\tslib.pyx[0m in [0;36mpandas._libs.tslib.array_to_datetime[1;34m()[0m

[1;31mTypeError[0m: invalid string coercion to datetime

During handling of the above exception, another exception occurred:

[1;31mValueError[0m                                Traceback (most recent call last)
[1;32mC:\ProgramData\Anaconda3\lib\site-packages\dateutil\parser\_parser.py[0m in [0;36mparse[1;34m(self, timestr, default, ignoretz, tzinfos, **kwargs)[0m
[0;32m    654[0m         [1;32mtry[0m[1;33m:[0m[1;33m[0m[1;33m[0m[0m
[1;32m--> 655[1;33m             [0mret[0m [1;33m=[0m [0mself[0m[1;33m.[0m[0m_build_naive[0m[1;33m([0m[0mres[0m[1;33m,[0m [0mdefault[0m[1;33m)[0m[1;33m[0m[1;33m[0m[0m
[0m[0;32m    656[0m         [1;32mexcept[0m [0mValueError[0m [1;32mas[0m [0me[0m[1;33m:[0m[1;33m[0m[1;33m[0m[0m

[1;32mC:\ProgramData\Anaconda3\lib\site-packages\dateutil\parser\_parser.py[0m in [0;36m_build_naive[1;34m(self, res, default)[0m
[0;32m   1240[0m [1;33m[0m[0m
[1;32m-> 1241[1;33m         [0mnaive[0m [1;33m=[0m [0mdefault[0m[1;33m.[0m[0mreplace[0m[1;33m([0m[1;33m**[0m[0mrepl[0m[1;33m)[0m[1;33m[0m[1;33m[0m[0m
[0m[0;32m   1242[0m [1;33m[0m[0m

[1;31mValueError[0m: month must be in 1..12

The above exception was the direct cause of the following exception:

[1;31mParserError[0m                               Traceback (most recent call last)
[1;32m<ipython-input-9-f2f3c275f194>[0m in [0;36m<module>[1;34m[0m
[1;32m----> 1[1;33m [0mdf[0m[1;33m[[0m[1;34m'æ—¥æœŸ'[0m[1;33m][0m [1;33m=[0m [0mpd[0m[1;33m.[0m[0mto_datetime[0m[1;33m([0m[0mdf[0m[1;33m[[0m[1;34m'æ—¥æœŸ'[0m[1;33m][0m[1;33m)[0m[1;33m[0m[1;33m[0m[0m
[0m[0;32m      2[0m [0mdf[0m[1;33m.[0m[0mhead[0m[1;33m([0m[1;33m)[0m[1;33m[0m[1;33m[0m[0m

[1;32mC:\ProgramData\Anaconda3\lib\site-packages\pandas\core\tools\datetimes.py[0m in [0;36mto_datetime[1;34m(arg, errors, dayfirst, yearfirst, utc, format, exact, unit, infer_datetime_format, origin, cache)[0m
[0;32m    803[0m             [0mresult[0m [1;33m=[0m [0marg[0m[1;33m.[0m[0mmap[0m[1;33m([0m[0mcache_array[0m[1;33m)[0m[1;33m[0m[1;33m[0m[0m
[0;32m    804[0m         [1;32melse[0m[1;33m:[0m[1;33m[0m[1;33m[0m[0m
[1;32m--> 805[1;33m             [0mvalues[0m [1;33m=[0m [0mconvert_listlike[0m[1;33m([0m[0marg[0m[1;33m.[0m[0m_values[0m[1;33m,[0m [0mformat[0m[1;33m)[0m[1;33m[0m[1;33m[0m[0m
[0m[0;32m    806[0m             [0mresult[0m [1;33m=[0m [0marg[0m[1;33m.[0m[0m_constructor[0m[1;33m([0m[0mvalues[0m[1;33m,[0m [0mindex[0m[1;33m=[0m[0marg[0m[1;33m.[0m[0mindex[0m[1;33m,[0m [0mname[0m[1;33m=[0m[0marg[0m[1;33m.[0m[0mname[0m[1;33m)[0m[1;33m[0m[1;33m[0m[0m
[0;32m    807[0m     [1;32melif[0m [0misinstance[0m[1;33m([0m[0marg[0m[1;33m,[0m [1;33m([0m[0mABCDataFrame[0m[1;33m,[0m [0mabc[0m[1;33m.[0m[0mMutableMapping[0m[1;33m)[0m[1;33m)[0m[1;33m:[0m[1;33m[0m[1;33m[0m[0m

[1;32mC:\ProgramData\Anaconda3\lib\site-packages\pandas\core\tools\datetimes.py[0m in [0;36m_convert_listlike_datetimes[1;34m(arg, format, name, tz, unit, errors, infer_datetime_format, dayfirst, yearfirst, exact)[0m
[0;32m    463[0m         [1;32massert[0m [0mformat[0m [1;32mis[0m [1;32mNone[0m [1;32mor[0m [0minfer_datetime_format[0m[1;33m[0m[1;33m[0m[0m
[0;32m    464[0m         [0mutc[0m [1;33m=[0m [0mtz[0m [1;33m==[0m [1;34m"utc"[0m[1;33m[0m[1;33m[0m[0m
[1;32m--> 465[1;33m         result, tz_parsed = objects_to_datetime64ns(
[0m[0;32m    466[0m             [0marg[0m[1;33m,[0m[1;33m[0m[1;33m[0m[0m
[0;32m    467[0m             [0mdayfirst[0m[1;33m=[0m[0mdayfirst[0m[1;33m,[0m[1;33m[0m[1;33m[0m[0m

[1;32mC:\ProgramData\Anaconda3\lib\site-packages\pandas\core\arrays\datetimes.py[0m in [0;36mobjects_to_datetime64ns[1;34m(data, dayfirst, yearfirst, utc, errors, require_iso8601, allow_object)[0m
[0;32m   2088[0m             [1;32mreturn[0m [0mvalues[0m[1;33m.[0m[0mview[0m[1;33m([0m[1;34m"i8"[0m[1;33m)[0m[1;33m,[0m [0mtz_parsed[0m[1;33m[0m[1;33m[0m[0m
[0;32m   2089[0m         [1;32mexcept[0m [1;33m([0m[0mValueError[0m[1;33m,[0m [0mTypeError[0m[1;33m)[0m[1;33m:[0m[1;33m[0m[1;33m[0m[0m
[1;32m-> 2090[1;33m             [1;32mraise[0m [0me[0m[1;33m[0m[1;33m[0m[0m
[0m[0;32m   2091[0m [1;33m[0m[0m
[0;32m   2092[0m     [1;32mif[0m [0mtz_parsed[0m [1;32mis[0m [1;32mnot[0m [1;32mNone[0m[1;33m:[0m[1;33m[0m[1;33m[0m[0m

[1;32mC:\ProgramData\Anaconda3\lib\site-packages\pandas\core\arrays\datetimes.py[0m in [0;36mobjects_to_datetime64ns[1;34m(data, dayfirst, yearfirst, utc, errors, require_iso8601, allow_object)[0m
[0;32m   2073[0m [1;33m[0m[0m
[0;32m   2074[0m     [1;32mtry[0m[1;33m:[0m[1;33m[0m[1;33m[0m[0m
[1;32m-> 2075[1;33m         result, tz_parsed = tslib.array_to_datetime(
[0m[0;32m   2076[0m             [0mdata[0m[1;33m,[0m[1;33m[0m[1;33m[0m[0m
[0;32m   2077[0m             [0merrors[0m[1;33m=[0m[0merrors[0m[1;33m,[0m[1;33m[0m[1;33m[0m[0m

[1;32mpandas\_libs\tslib.pyx[0m in [0;36mpandas._libs.tslib.array_to_datetime[1;34m()[0m

[1;32mpandas\_libs\tslib.pyx[0m in [0;36mpandas._libs.tslib.array_to_datetime[1;34m()[0m

[1;32mpandas\_libs\tslib.pyx[0m in [0;36mpandas._libs.tslib.array_to_datetime_object[1;34m()[0m

[1;32mpandas\_libs\tslib.pyx[0m in [0;36mpandas._libs.tslib.array_to_datetime_object[1;34m()[0m

[1;32mpandas\_libs\tslibs\parsing.pyx[0m in [0;36mpandas._libs.tslibs.parsing.parse_datetime_string[1;34m()[0m

[1;32mC:\ProgramData\Anaconda3\lib\site-packages\dateutil\parser\_parser.py[0m in [0;36mparse[1;34m(timestr, parserinfo, **kwargs)[0m
[0;32m   1372[0m         [1;32mreturn[0m [0mparser[0m[1;33m([0m[0mparserinfo[0m[1;33m)[0m[1;33m.[0m[0mparse[0m[1;33m([0m[0mtimestr[0m[1;33m,[0m [1;33m**[0m[0mkwargs[0m[1;33m)[0m[1;33m[0m[1;33m[0m[0m
[0;32m   1373[0m     [1;32melse[0m[1;33m:[0m[1;33m[0m[1;33m[0m[0m
[1;32m-> 1374[1;33m         [1;32mreturn[0m [0mDEFAULTPARSER[0m[1;33m.[0m[0mparse[0m[1;33m([0m[0mtimestr[0m[1;33m,[0m [1;33m**[0m[0mkwargs[0m[1;33m)[0m[1;33m[0m[1;33m[0m[0m
[0m[0;32m   1375[0m [1;33m[0m[0m
[0;32m   1376[0m [1;33m[0m[0m

[1;32mC:\ProgramData\Anaconda3\lib\site-packages\dateutil\parser\_parser.py[0m in [0;36mparse[1;34m(self, timestr, default, ignoretz, tzinfos, **kwargs)[0m
[0;32m    655[0m             [0mret[0m [1;33m=[0m [0mself[0m[1;33m.[0m[0m_build_naive[0m[1;33m([0m[0mres[0m[1;33m,[0m [0mdefault[0m[1;33m)[0m[1;33m[0m[1;33m[0m[0m
[0;32m    656[0m         [1;32mexcept[0m [0mValueError[0m [1;32mas[0m [0me[0m[1;33m:[0m[1;33m[0m[1;33m[0m[0m
[1;32m--> 657[1;33m             [0msix[0m[1;33m.[0m[0mraise_from[0m[1;33m([0m[0mParserError[0m[1;33m([0m[0me[0m[1;33m.[0m[0margs[0m[1;33m[[0m[1;36m0[0m[1;33m][0m [1;33m+[0m [1;34m": %s"[0m[1;33m,[0m [0mtimestr[0m[1;33m)[0m[1;33m,[0m [0me[0m[1;33m)[0m[1;33m[0m[1;33m[0m[0m
[0m[0;32m    658[0m [1;33m[0m[0m
[0;32m    659[0m         [1;32mif[0m [1;32mnot[0m [0mignoretz[0m[1;33m:[0m[1;33m[0m[1;33m[0m[0m

[1;32mC:\ProgramData\Anaconda3\lib\site-packages\six.py[0m in [0;36mraise_from[1;34m(value, from_value)[0m

[1;31mParserError[0m: month must be in 1..12: 2113--0-01
ParserError: month must be in 1..12: 2113--0-01

